<?xml version="1.0" encoding="UTF-8"?>
<!-- Generated by org.testng.reporters.JUnitXMLReporter -->
<testsuite hostname="ASDP1547PO01976" ignored="0" name="Default test" tests="7" failures="1" timestamp="17 Jul 2017 13:36:22 GMT" time="0.17" errors="0">
  <testcase name="registerPlayerTest" time="0.082" classname="com.qainfotech.tap.training.snl.api.BoardTest"/>
  <testcase name="registerPlayerTestForGameInProgressException" time="0.006" classname="com.qainfotech.tap.training.snl.api.BoardTest">
    <failure type="org.testng.TestException" message="
Method BoardTest.registerPlayerTestForGameInProgressException()[pri:0, instance:com.qainfotech.tap.training.snl.api.BoardTest@5dfcfece] should have thrown an exception of type class com.qainfotech.tap.training.snl.api.GameInProgressException">
      <![CDATA[org.testng.TestException: 
Method BoardTest.registerPlayerTestForGameInProgressException()[pri:0, instance:com.qainfotech.tap.training.snl.api.BoardTest@5dfcfece] should have thrown an exception of type class com.qainfotech.tap.training.snl.api.GameInProgressException
	at org.testng.internal.ExpectedExceptionsHolder.noException(ExpectedExceptionsHolder.java:89)
	at org.testng.internal.Invoker.handleInvocationResults(Invoker.java:1416)
	at org.testng.internal.Invoker.invokeMethod(Invoker.java:695)
	at org.testng.internal.Invoker.invokeTestMethod(Invoker.java:869)
	at org.testng.internal.Invoker.invokeTestMethods(Invoker.java:1193)
	at org.testng.internal.TestMethodWorker.invokeTestMethods(TestMethodWorker.java:126)
	at org.testng.internal.TestMethodWorker.run(TestMethodWorker.java:109)
	at org.testng.TestRunner.privateRun(TestRunner.java:744)
	at org.testng.TestRunner.run(TestRunner.java:602)
	at org.testng.SuiteRunner.runTest(SuiteRunner.java:380)
	at org.testng.SuiteRunner.runSequentially(SuiteRunner.java:375)
	at org.testng.SuiteRunner.privateRun(SuiteRunner.java:340)
	at org.testng.SuiteRunner.run(SuiteRunner.java:289)
	at org.testng.SuiteRunnerWorker.runSuite(SuiteRunnerWorker.java:52)
	at org.testng.SuiteRunnerWorker.run(SuiteRunnerWorker.java:86)
	at org.testng.TestNG.runSuitesSequentially(TestNG.java:1301)
	at org.testng.TestNG.runSuitesLocally(TestNG.java:1226)
	at org.testng.TestNG.runSuites(TestNG.java:1144)
	at org.testng.TestNG.run(TestNG.java:1115)
	at org.testng.remote.AbstractRemoteTestNG.run(AbstractRemoteTestNG.java:132)
	at org.testng.remote.RemoteTestNG.initAndRun(RemoteTestNG.java:230)
	at org.testng.remote.RemoteTestNG.main(RemoteTestNG.java:76)
]]>
    </failure>
  </testcase> <!-- registerPlayerTestForGameInProgressException -->
  <testcase name="registerPlayerTestForMaxPlayerException" time="0.016" classname="com.qainfotech.tap.training.snl.api.BoardTest"/>
  <testcase name="registerPlayerTestForPlayerExistException" time="0.011" classname="com.qainfotech.tap.training.snl.api.BoardTest"/>
  <testcase name="dataTest" time="0.004" classname="com.qainfotech.tap.training.snl.api.BoardModelTest"/>
  <testcase name="initTest" time="0.005" classname="com.qainfotech.tap.training.snl.api.BoardModelTest"/>
  <testcase name="saveTest" time="0.008" classname="com.qainfotech.tap.training.snl.api.BoardModelTest"/>
</testsuite> <!-- Default test -->
